Typescript/backend-nestjs-task/storage/output/trades.json
[
  {
    "pair": "BTC/USDC",
    "buyOrderId": "2",
    "sellOrderId": "1",
    "price": "63500",
    "amount": "0.0023",
    "ts": 1746262879460
  },
  {
    "pair": "BTC/USDC",
    "buyOrderId": "3",
    "sellOrderId": "4",
    "price": "62880.54",
    "amount": "0.00798",
    "ts": 1746262879461
  },
  {
    "pair": "BTC/USDC",
    "buyOrderId": "7",
    "sellOrderId": "6",
    "price": "47500",
    "amount": "0.2",
    "ts": 1746262879462
  },
  {
    "pair": "BTC/USDC",
    "buyOrderId": "9",
    "sellOrderId": "8",
    "price": "61577.3",
    "amount": "2.345",
    "ts": 1746262879463
  },
  {
    "pair": "BTC/USDC",
    "buyOrderId": "10",
    "sellOrderId": "8",
    "price": "61577.3",
    "amount": "2",
    "ts": 1746262879463
  },
  {
    "pair": "BTC/USDC",
    "buyOrderId": "11",
    "sellOrderId": "8",
    "price": "61577.3",
    "amount": "0.5",
    "ts": 1746262879463
  },
  {
    "pair": "BTC/USDC",
    "buyOrderId": "12",
    "sellOrderId": "8",
    "price": "61577.3",
    "amount": "1.5",
    "ts": 1746262879464
  }
]
